[2024-02-29T04:38:26.949+0000] {taskinstance.py:1979} INFO - Dependencies all met for dep_context=non-requeueable deps ti=<TaskInstance: run_pipeline_new.download_load_data scheduled__2021-01-01T00:00:00+00:00 [queued]>
[2024-02-29T04:38:26.963+0000] {taskinstance.py:1979} INFO - Dependencies all met for dep_context=requeueable deps ti=<TaskInstance: run_pipeline_new.download_load_data scheduled__2021-01-01T00:00:00+00:00 [queued]>
[2024-02-29T04:38:26.964+0000] {taskinstance.py:2193} INFO - Starting attempt 3 of 3
[2024-02-29T04:38:26.980+0000] {taskinstance.py:2214} INFO - Executing <Task(PythonOperator): download_load_data> on 2021-01-01 00:00:00+00:00
[2024-02-29T04:38:26.986+0000] {standard_task_runner.py:60} INFO - Started process 1225383 to run task
[2024-02-29T04:38:26.990+0000] {standard_task_runner.py:87} INFO - Running: ['airflow', 'tasks', 'run', 'run_pipeline_new', 'download_load_data', 'scheduled__2021-01-01T00:00:00+00:00', '--job-id', '15', '--raw', '--subdir', 'DAGS_FOLDER/run_pipeline.py', '--cfg-path', '/tmp/tmpcpqepdv0']
[2024-02-29T04:38:26.992+0000] {standard_task_runner.py:88} INFO - Job 15: Subtask download_load_data
[2024-02-29T04:38:27.101+0000] {task_command.py:423} INFO - Running <TaskInstance: run_pipeline_new.download_load_data scheduled__2021-01-01T00:00:00+00:00 [running]> on host idowu-pc
[2024-02-29T04:38:27.299+0000] {logging_mixin.py:188} WARNING - /home/idowuileks/Desktop/tech_project/nyc_taxi_project/docker_sql/ny_taxi_test/dbtairflowenv/lib/python3.10/site-packages/airflow/utils/context.py:207 AirflowContextDeprecationWarning: Accessing 'execution_date' from the template is deprecated and will be removed in a future version. Please use 'data_interval_start' or 'logical_date' instead.
[2024-02-29T04:38:27.369+0000] {taskinstance.py:2510} INFO - Exporting env vars: AIRFLOW_CTX_DAG_EMAIL='' AIRFLOW_CTX_DAG_OWNER='airflow' AIRFLOW_CTX_DAG_ID='run_pipeline_new' AIRFLOW_CTX_TASK_ID='download_load_data' AIRFLOW_CTX_EXECUTION_DATE='2021-01-01T00:00:00+00:00' AIRFLOW_CTX_TRY_NUMBER='3' AIRFLOW_CTX_DAG_RUN_ID='scheduled__2021-01-01T00:00:00+00:00'
[2024-02-29T04:38:27.370+0000] {logging_mixin.py:188} INFO - /2021_data
[2024-02-29T04:38:27.370+0000] {taskinstance.py:2728} ERROR - Task failed with exception
Traceback (most recent call last):
  File "/home/idowuileks/Desktop/tech_project/nyc_taxi_project/docker_sql/ny_taxi_test/dbtairflowenv/lib/python3.10/site-packages/airflow/models/taskinstance.py", line 444, in _execute_task
    result = _execute_callable(context=context, **execute_callable_kwargs)
  File "/home/idowuileks/Desktop/tech_project/nyc_taxi_project/docker_sql/ny_taxi_test/dbtairflowenv/lib/python3.10/site-packages/airflow/models/taskinstance.py", line 414, in _execute_callable
    return execute_callable(context=context, **execute_callable_kwargs)
  File "/home/idowuileks/Desktop/tech_project/nyc_taxi_project/docker_sql/ny_taxi_test/dbtairflowenv/lib/python3.10/site-packages/airflow/operators/python.py", line 200, in execute
    return_value = self.execute_callable()
  File "/home/idowuileks/Desktop/tech_project/nyc_taxi_project/docker_sql/ny_taxi_test/dbtairflowenv/lib/python3.10/site-packages/airflow/operators/python.py", line 217, in execute_callable
    return self.python_callable(*self.op_args, **self.op_kwargs)
  File "/home/idowuileks/Desktop/tech_project/nyc_taxi_project/docker_sql/etl_script/ny_run_etl_pipeline.py", line 27, in download_load_data
    data_path, folder_path = download_store_data(year, month, parent_folder_path=parent_folder_path, create_new_folder=create_new_folder)
  File "/home/idowuileks/Desktop/tech_project/nyc_taxi_project/docker_sql/etl_script/ny_taxi_extract.py", line 20, in download_store_data
    os.makedirs(file_path, exist_ok=True,mode=0o777)
  File "/usr/lib/python3.10/os.py", line 225, in makedirs
    mkdir(name, mode)
PermissionError: [Errno 13] Permission denied: '/2021_data'
[2024-02-29T04:38:27.391+0000] {taskinstance.py:1149} INFO - Marking task as FAILED. dag_id=run_pipeline_new, task_id=download_load_data, execution_date=20210101T000000, start_date=20240229T043826, end_date=20240229T043827
[2024-02-29T04:38:27.400+0000] {standard_task_runner.py:107} ERROR - Failed to execute job 15 for task download_load_data ([Errno 13] Permission denied: '/2021_data'; 1225383)
[2024-02-29T04:38:27.443+0000] {local_task_job_runner.py:234} INFO - Task exited with return code 1
