[2024-02-29T04:17:41.036+0000] {taskinstance.py:1979} INFO - Dependencies all met for dep_context=non-requeueable deps ti=<TaskInstance: run_pipeline_new.download_load_data scheduled__2022-02-01T00:00:00+00:00 [queued]>
[2024-02-29T04:17:41.047+0000] {taskinstance.py:1979} INFO - Dependencies all met for dep_context=requeueable deps ti=<TaskInstance: run_pipeline_new.download_load_data scheduled__2022-02-01T00:00:00+00:00 [queued]>
[2024-02-29T04:17:41.048+0000] {taskinstance.py:2193} INFO - Starting attempt 1 of 3
[2024-02-29T04:17:41.067+0000] {taskinstance.py:2214} INFO - Executing <Task(PythonOperator): download_load_data> on 2022-02-01 00:00:00+00:00
[2024-02-29T04:17:41.074+0000] {standard_task_runner.py:60} INFO - Started process 1202779 to run task
[2024-02-29T04:17:41.080+0000] {standard_task_runner.py:87} INFO - Running: ['airflow', 'tasks', 'run', 'run_pipeline_new', 'download_load_data', 'scheduled__2022-02-01T00:00:00+00:00', '--job-id', '4', '--raw', '--subdir', 'DAGS_FOLDER/run_pipeline.py', '--cfg-path', '/tmp/tmpdt2td_t8']
[2024-02-29T04:17:41.082+0000] {standard_task_runner.py:88} INFO - Job 4: Subtask download_load_data
[2024-02-29T04:17:41.173+0000] {task_command.py:423} INFO - Running <TaskInstance: run_pipeline_new.download_load_data scheduled__2022-02-01T00:00:00+00:00 [running]> on host idowu-pc
[2024-02-29T04:17:41.341+0000] {logging_mixin.py:188} WARNING - /home/idowuileks/Desktop/tech_project/nyc_taxi_project/docker_sql/ny_taxi_test/dbtairflowenv/lib/python3.10/site-packages/airflow/utils/context.py:207 AirflowContextDeprecationWarning: Accessing 'execution_date' from the template is deprecated and will be removed in a future version. Please use 'data_interval_start' or 'logical_date' instead.
[2024-02-29T04:17:41.398+0000] {taskinstance.py:2510} INFO - Exporting env vars: AIRFLOW_CTX_DAG_EMAIL='' AIRFLOW_CTX_DAG_OWNER='airflow' AIRFLOW_CTX_DAG_ID='run_pipeline_new' AIRFLOW_CTX_TASK_ID='download_load_data' AIRFLOW_CTX_EXECUTION_DATE='2022-02-01T00:00:00+00:00' AIRFLOW_CTX_TRY_NUMBER='1' AIRFLOW_CTX_DAG_RUN_ID='scheduled__2022-02-01T00:00:00+00:00'
[2024-02-29T04:17:41.399+0000] {taskinstance.py:2728} ERROR - Task failed with exception
Traceback (most recent call last):
  File "/home/idowuileks/Desktop/tech_project/nyc_taxi_project/docker_sql/ny_taxi_test/dbtairflowenv/lib/python3.10/site-packages/airflow/models/taskinstance.py", line 444, in _execute_task
    result = _execute_callable(context=context, **execute_callable_kwargs)
  File "/home/idowuileks/Desktop/tech_project/nyc_taxi_project/docker_sql/ny_taxi_test/dbtairflowenv/lib/python3.10/site-packages/airflow/models/taskinstance.py", line 414, in _execute_callable
    return execute_callable(context=context, **execute_callable_kwargs)
  File "/home/idowuileks/Desktop/tech_project/nyc_taxi_project/docker_sql/ny_taxi_test/dbtairflowenv/lib/python3.10/site-packages/airflow/operators/python.py", line 200, in execute
    return_value = self.execute_callable()
  File "/home/idowuileks/Desktop/tech_project/nyc_taxi_project/docker_sql/ny_taxi_test/dbtairflowenv/lib/python3.10/site-packages/airflow/operators/python.py", line 217, in execute_callable
    return self.python_callable(*self.op_args, **self.op_kwargs)
  File "/home/idowuileks/Desktop/tech_project/nyc_taxi_project/docker_sql/etl_script/ny_run_etl_pipeline.py", line 27, in download_load_data
    data_path, folder_path = download_store_data(year, month, parent_folder_path=parent_folder_path, create_new_folder=create_new_folder)
  File "/home/idowuileks/Desktop/tech_project/nyc_taxi_project/docker_sql/etl_script/ny_taxi_extract.py", line 19, in download_store_data
    os.makedirs(file_path, exist_ok=True,mode=0o777)
  File "/usr/lib/python3.10/os.py", line 225, in makedirs
    mkdir(name, mode)
PermissionError: [Errno 13] Permission denied: '/2022_data'
[2024-02-29T04:17:41.421+0000] {taskinstance.py:1149} INFO - Marking task as UP_FOR_RETRY. dag_id=run_pipeline_new, task_id=download_load_data, execution_date=20220201T000000, start_date=20240229T041741, end_date=20240229T041741
[2024-02-29T04:17:41.431+0000] {standard_task_runner.py:107} ERROR - Failed to execute job 4 for task download_load_data ([Errno 13] Permission denied: '/2022_data'; 1202779)
[2024-02-29T04:17:41.450+0000] {local_task_job_runner.py:234} INFO - Task exited with return code 1
[2024-02-29T04:23:18.605+0000] {taskinstance.py:1979} INFO - Dependencies all met for dep_context=non-requeueable deps ti=<TaskInstance: run_pipeline_new.download_load_data scheduled__2022-02-01T00:00:00+00:00 [queued]>
[2024-02-29T04:23:18.614+0000] {taskinstance.py:1979} INFO - Dependencies all met for dep_context=requeueable deps ti=<TaskInstance: run_pipeline_new.download_load_data scheduled__2022-02-01T00:00:00+00:00 [queued]>
[2024-02-29T04:23:18.615+0000] {taskinstance.py:2193} INFO - Starting attempt 1 of 3
[2024-02-29T04:23:18.632+0000] {taskinstance.py:2214} INFO - Executing <Task(PythonOperator): download_load_data> on 2022-02-01 00:00:00+00:00
[2024-02-29T04:23:18.636+0000] {standard_task_runner.py:60} INFO - Started process 1209491 to run task
[2024-02-29T04:23:18.640+0000] {standard_task_runner.py:87} INFO - Running: ['airflow', 'tasks', 'run', 'run_pipeline_new', 'download_load_data', 'scheduled__2022-02-01T00:00:00+00:00', '--job-id', '5', '--raw', '--subdir', 'DAGS_FOLDER/run_pipeline.py', '--cfg-path', '/tmp/tmp0zt1blm4']
[2024-02-29T04:23:18.642+0000] {standard_task_runner.py:88} INFO - Job 5: Subtask download_load_data
[2024-02-29T04:23:18.733+0000] {task_command.py:423} INFO - Running <TaskInstance: run_pipeline_new.download_load_data scheduled__2022-02-01T00:00:00+00:00 [running]> on host idowu-pc
[2024-02-29T04:23:18.932+0000] {logging_mixin.py:188} WARNING - /home/idowuileks/Desktop/tech_project/nyc_taxi_project/docker_sql/ny_taxi_test/dbtairflowenv/lib/python3.10/site-packages/airflow/utils/context.py:207 AirflowContextDeprecationWarning: Accessing 'execution_date' from the template is deprecated and will be removed in a future version. Please use 'data_interval_start' or 'logical_date' instead.
[2024-02-29T04:23:18.994+0000] {taskinstance.py:2510} INFO - Exporting env vars: AIRFLOW_CTX_DAG_EMAIL='' AIRFLOW_CTX_DAG_OWNER='airflow' AIRFLOW_CTX_DAG_ID='run_pipeline_new' AIRFLOW_CTX_TASK_ID='download_load_data' AIRFLOW_CTX_EXECUTION_DATE='2022-02-01T00:00:00+00:00' AIRFLOW_CTX_TRY_NUMBER='1' AIRFLOW_CTX_DAG_RUN_ID='scheduled__2022-02-01T00:00:00+00:00'
[2024-02-29T04:23:18.995+0000] {logging_mixin.py:188} INFO - /2022_data
[2024-02-29T04:23:18.995+0000] {taskinstance.py:2728} ERROR - Task failed with exception
Traceback (most recent call last):
  File "/home/idowuileks/Desktop/tech_project/nyc_taxi_project/docker_sql/ny_taxi_test/dbtairflowenv/lib/python3.10/site-packages/airflow/models/taskinstance.py", line 444, in _execute_task
    result = _execute_callable(context=context, **execute_callable_kwargs)
  File "/home/idowuileks/Desktop/tech_project/nyc_taxi_project/docker_sql/ny_taxi_test/dbtairflowenv/lib/python3.10/site-packages/airflow/models/taskinstance.py", line 414, in _execute_callable
    return execute_callable(context=context, **execute_callable_kwargs)
  File "/home/idowuileks/Desktop/tech_project/nyc_taxi_project/docker_sql/ny_taxi_test/dbtairflowenv/lib/python3.10/site-packages/airflow/operators/python.py", line 200, in execute
    return_value = self.execute_callable()
  File "/home/idowuileks/Desktop/tech_project/nyc_taxi_project/docker_sql/ny_taxi_test/dbtairflowenv/lib/python3.10/site-packages/airflow/operators/python.py", line 217, in execute_callable
    return self.python_callable(*self.op_args, **self.op_kwargs)
  File "/home/idowuileks/Desktop/tech_project/nyc_taxi_project/docker_sql/etl_script/ny_run_etl_pipeline.py", line 27, in download_load_data
    data_path, folder_path = download_store_data(year, month, parent_folder_path=parent_folder_path, create_new_folder=create_new_folder)
  File "/home/idowuileks/Desktop/tech_project/nyc_taxi_project/docker_sql/etl_script/ny_taxi_extract.py", line 20, in download_store_data
    os.makedirs(file_path, exist_ok=True,mode=0o777)
  File "/usr/lib/python3.10/os.py", line 225, in makedirs
    mkdir(name, mode)
PermissionError: [Errno 13] Permission denied: '/2022_data'
[2024-02-29T04:23:19.016+0000] {taskinstance.py:1149} INFO - Marking task as UP_FOR_RETRY. dag_id=run_pipeline_new, task_id=download_load_data, execution_date=20220201T000000, start_date=20240229T042318, end_date=20240229T042319
[2024-02-29T04:23:19.028+0000] {standard_task_runner.py:107} ERROR - Failed to execute job 5 for task download_load_data ([Errno 13] Permission denied: '/2022_data'; 1209491)
[2024-02-29T04:23:19.053+0000] {local_task_job_runner.py:234} INFO - Task exited with return code 1
