[2024-02-29T04:17:40.944+0000] {taskinstance.py:1979} INFO - Dependencies all met for dep_context=non-requeueable deps ti=<TaskInstance: run_pipeline_new.download_load_data scheduled__2022-03-01T00:00:00+00:00 [queued]>
[2024-02-29T04:17:40.954+0000] {taskinstance.py:1979} INFO - Dependencies all met for dep_context=requeueable deps ti=<TaskInstance: run_pipeline_new.download_load_data scheduled__2022-03-01T00:00:00+00:00 [queued]>
[2024-02-29T04:17:40.954+0000] {taskinstance.py:2193} INFO - Starting attempt 1 of 3
[2024-02-29T04:17:40.971+0000] {taskinstance.py:2214} INFO - Executing <Task(PythonOperator): download_load_data> on 2022-03-01 00:00:00+00:00
[2024-02-29T04:17:40.978+0000] {standard_task_runner.py:60} INFO - Started process 1202771 to run task
[2024-02-29T04:17:40.981+0000] {standard_task_runner.py:87} INFO - Running: ['airflow', 'tasks', 'run', 'run_pipeline_new', 'download_load_data', 'scheduled__2022-03-01T00:00:00+00:00', '--job-id', '3', '--raw', '--subdir', 'DAGS_FOLDER/run_pipeline.py', '--cfg-path', '/tmp/tmpff44gv0x']
[2024-02-29T04:17:40.983+0000] {standard_task_runner.py:88} INFO - Job 3: Subtask download_load_data
[2024-02-29T04:17:41.090+0000] {task_command.py:423} INFO - Running <TaskInstance: run_pipeline_new.download_load_data scheduled__2022-03-01T00:00:00+00:00 [running]> on host idowu-pc
[2024-02-29T04:17:41.284+0000] {logging_mixin.py:188} WARNING - /home/idowuileks/Desktop/tech_project/nyc_taxi_project/docker_sql/ny_taxi_test/dbtairflowenv/lib/python3.10/site-packages/airflow/utils/context.py:207 AirflowContextDeprecationWarning: Accessing 'execution_date' from the template is deprecated and will be removed in a future version. Please use 'data_interval_start' or 'logical_date' instead.
[2024-02-29T04:17:41.340+0000] {taskinstance.py:2510} INFO - Exporting env vars: AIRFLOW_CTX_DAG_EMAIL='' AIRFLOW_CTX_DAG_OWNER='airflow' AIRFLOW_CTX_DAG_ID='run_pipeline_new' AIRFLOW_CTX_TASK_ID='download_load_data' AIRFLOW_CTX_EXECUTION_DATE='2022-03-01T00:00:00+00:00' AIRFLOW_CTX_TRY_NUMBER='1' AIRFLOW_CTX_DAG_RUN_ID='scheduled__2022-03-01T00:00:00+00:00'
[2024-02-29T04:17:41.341+0000] {taskinstance.py:2728} ERROR - Task failed with exception
Traceback (most recent call last):
  File "/home/idowuileks/Desktop/tech_project/nyc_taxi_project/docker_sql/ny_taxi_test/dbtairflowenv/lib/python3.10/site-packages/airflow/models/taskinstance.py", line 444, in _execute_task
    result = _execute_callable(context=context, **execute_callable_kwargs)
  File "/home/idowuileks/Desktop/tech_project/nyc_taxi_project/docker_sql/ny_taxi_test/dbtairflowenv/lib/python3.10/site-packages/airflow/models/taskinstance.py", line 414, in _execute_callable
    return execute_callable(context=context, **execute_callable_kwargs)
  File "/home/idowuileks/Desktop/tech_project/nyc_taxi_project/docker_sql/ny_taxi_test/dbtairflowenv/lib/python3.10/site-packages/airflow/operators/python.py", line 200, in execute
    return_value = self.execute_callable()
  File "/home/idowuileks/Desktop/tech_project/nyc_taxi_project/docker_sql/ny_taxi_test/dbtairflowenv/lib/python3.10/site-packages/airflow/operators/python.py", line 217, in execute_callable
    return self.python_callable(*self.op_args, **self.op_kwargs)
  File "/home/idowuileks/Desktop/tech_project/nyc_taxi_project/docker_sql/etl_script/ny_run_etl_pipeline.py", line 27, in download_load_data
    data_path, folder_path = download_store_data(year, month, parent_folder_path=parent_folder_path, create_new_folder=create_new_folder)
  File "/home/idowuileks/Desktop/tech_project/nyc_taxi_project/docker_sql/etl_script/ny_taxi_extract.py", line 19, in download_store_data
    os.makedirs(file_path, exist_ok=True,mode=0o777)
  File "/usr/lib/python3.10/os.py", line 225, in makedirs
    mkdir(name, mode)
PermissionError: [Errno 13] Permission denied: '/2022_data'
[2024-02-29T04:17:41.359+0000] {taskinstance.py:1149} INFO - Marking task as UP_FOR_RETRY. dag_id=run_pipeline_new, task_id=download_load_data, execution_date=20220301T000000, start_date=20240229T041740, end_date=20240229T041741
[2024-02-29T04:17:41.370+0000] {standard_task_runner.py:107} ERROR - Failed to execute job 3 for task download_load_data ([Errno 13] Permission denied: '/2022_data'; 1202771)
[2024-02-29T04:17:41.393+0000] {local_task_job_runner.py:234} INFO - Task exited with return code 1
[2024-02-29T04:23:18.810+0000] {taskinstance.py:1979} INFO - Dependencies all met for dep_context=non-requeueable deps ti=<TaskInstance: run_pipeline_new.download_load_data scheduled__2022-03-01T00:00:00+00:00 [queued]>
[2024-02-29T04:23:18.819+0000] {taskinstance.py:1979} INFO - Dependencies all met for dep_context=requeueable deps ti=<TaskInstance: run_pipeline_new.download_load_data scheduled__2022-03-01T00:00:00+00:00 [queued]>
[2024-02-29T04:23:18.819+0000] {taskinstance.py:2193} INFO - Starting attempt 1 of 3
[2024-02-29T04:23:18.836+0000] {taskinstance.py:2214} INFO - Executing <Task(PythonOperator): download_load_data> on 2022-03-01 00:00:00+00:00
[2024-02-29T04:23:18.841+0000] {standard_task_runner.py:60} INFO - Started process 1209507 to run task
[2024-02-29T04:23:18.845+0000] {standard_task_runner.py:87} INFO - Running: ['airflow', 'tasks', 'run', 'run_pipeline_new', 'download_load_data', 'scheduled__2022-03-01T00:00:00+00:00', '--job-id', '7', '--raw', '--subdir', 'DAGS_FOLDER/run_pipeline.py', '--cfg-path', '/tmp/tmp75elz2ic']
[2024-02-29T04:23:18.847+0000] {standard_task_runner.py:88} INFO - Job 7: Subtask download_load_data
[2024-02-29T04:23:18.944+0000] {task_command.py:423} INFO - Running <TaskInstance: run_pipeline_new.download_load_data scheduled__2022-03-01T00:00:00+00:00 [running]> on host idowu-pc
[2024-02-29T04:23:19.129+0000] {logging_mixin.py:188} WARNING - /home/idowuileks/Desktop/tech_project/nyc_taxi_project/docker_sql/ny_taxi_test/dbtairflowenv/lib/python3.10/site-packages/airflow/utils/context.py:207 AirflowContextDeprecationWarning: Accessing 'execution_date' from the template is deprecated and will be removed in a future version. Please use 'data_interval_start' or 'logical_date' instead.
[2024-02-29T04:23:19.185+0000] {taskinstance.py:2510} INFO - Exporting env vars: AIRFLOW_CTX_DAG_EMAIL='' AIRFLOW_CTX_DAG_OWNER='airflow' AIRFLOW_CTX_DAG_ID='run_pipeline_new' AIRFLOW_CTX_TASK_ID='download_load_data' AIRFLOW_CTX_EXECUTION_DATE='2022-03-01T00:00:00+00:00' AIRFLOW_CTX_TRY_NUMBER='1' AIRFLOW_CTX_DAG_RUN_ID='scheduled__2022-03-01T00:00:00+00:00'
[2024-02-29T04:23:19.187+0000] {logging_mixin.py:188} INFO - /2022_data
[2024-02-29T04:23:19.187+0000] {taskinstance.py:2728} ERROR - Task failed with exception
Traceback (most recent call last):
  File "/home/idowuileks/Desktop/tech_project/nyc_taxi_project/docker_sql/ny_taxi_test/dbtairflowenv/lib/python3.10/site-packages/airflow/models/taskinstance.py", line 444, in _execute_task
    result = _execute_callable(context=context, **execute_callable_kwargs)
  File "/home/idowuileks/Desktop/tech_project/nyc_taxi_project/docker_sql/ny_taxi_test/dbtairflowenv/lib/python3.10/site-packages/airflow/models/taskinstance.py", line 414, in _execute_callable
    return execute_callable(context=context, **execute_callable_kwargs)
  File "/home/idowuileks/Desktop/tech_project/nyc_taxi_project/docker_sql/ny_taxi_test/dbtairflowenv/lib/python3.10/site-packages/airflow/operators/python.py", line 200, in execute
    return_value = self.execute_callable()
  File "/home/idowuileks/Desktop/tech_project/nyc_taxi_project/docker_sql/ny_taxi_test/dbtairflowenv/lib/python3.10/site-packages/airflow/operators/python.py", line 217, in execute_callable
    return self.python_callable(*self.op_args, **self.op_kwargs)
  File "/home/idowuileks/Desktop/tech_project/nyc_taxi_project/docker_sql/etl_script/ny_run_etl_pipeline.py", line 27, in download_load_data
    data_path, folder_path = download_store_data(year, month, parent_folder_path=parent_folder_path, create_new_folder=create_new_folder)
  File "/home/idowuileks/Desktop/tech_project/nyc_taxi_project/docker_sql/etl_script/ny_taxi_extract.py", line 20, in download_store_data
    os.makedirs(file_path, exist_ok=True,mode=0o777)
  File "/usr/lib/python3.10/os.py", line 225, in makedirs
    mkdir(name, mode)
PermissionError: [Errno 13] Permission denied: '/2022_data'
[2024-02-29T04:23:19.204+0000] {taskinstance.py:1149} INFO - Marking task as UP_FOR_RETRY. dag_id=run_pipeline_new, task_id=download_load_data, execution_date=20220301T000000, start_date=20240229T042318, end_date=20240229T042319
[2024-02-29T04:23:19.214+0000] {standard_task_runner.py:107} ERROR - Failed to execute job 7 for task download_load_data ([Errno 13] Permission denied: '/2022_data'; 1209507)
[2024-02-29T04:23:19.258+0000] {local_task_job_runner.py:234} INFO - Task exited with return code 1
